<sdf version='1.6'>
  <world name='conveyor_world'>
    <physics name='default_physics' default='0' type='ode'>
      <max_step_size>0.00625</max_step_size>
      <real_time_factor>1</real_time_factor>
      <real_time_update_rate>160</real_time_update_rate>
    </physics>
    <scene>
      <shadows>0</shadows>
      <ambient>0.4 0.4 0.4 1</ambient>
      <background>0.7 0.7 0.7 1</background>
    </scene>
    <model name='ground_plane'>
      <static>1</static>
      <link name='link'>
        <collision name='collision'>
          <geometry>
            <plane>
              <normal>0 0 1</normal>
              <size>100 100</size>
            </plane>
          </geometry>
          <surface>
            <friction>
              <ode>
                <mu>100</mu>
                <mu2>50</mu2>
              </ode>
              <torsional>
                <ode/>
              </torsional>
            </friction>
            <contact>
              <ode/>
            </contact>
            <bounce/>
          </surface>
          <max_contacts>10</max_contacts>
        </collision>
        <visual name='visual'>
          <cast_shadows>0</cast_shadows>
          <geometry>
            <plane>
              <normal>0 0 1</normal>
              <size>100 100</size>
            </plane>
          </geometry>
          <material>
            <script>
              <uri>file://media/materials/scripts/gazebo.material</uri>
              <name>Gazebo/Grey</name>
            </script>
          </material>
        </visual>
        <self_collide>0</self_collide>
        <kinematic>0</kinematic>
        <gravity>1</gravity>
      </link>
    </model>
    <light name='sun' type='directional'>
      <cast_shadows>1</cast_shadows>
      <pose frame=''>0 0 10 0 -0 0</pose>
      <diffuse>0.8 0.8 0.8 1</diffuse>
      <specular>0.2 0.2 0.2 1</specular>
      <attenuation>
        <range>1000</range>
        <constant>0.9</constant>
        <linear>0.01</linear>
        <quadratic>0.001</quadratic>
      </attenuation>
      <direction>-0.5 0.1 -0.9</direction>
    </light>
    <model name='conveyor_belt'>
      <model name='conveyor_belt_fixed'>
        <static>1</static>
        <pose frame=''>0 0 0 0 -0 0</pose>
        <link name='link'>
          <pose frame=''>0 0.32 0 0 -0 0</pose>
          <visual name='visual_conveyor_model_1'>
            <geometry>
              <mesh>
                <uri>model://conveyor/meshes/model.dae</uri>
                <scale>1 1 1</scale>
              </mesh>
            </geometry>
          </visual>
          <self_collide>0</self_collide>
          <kinematic>0</kinematic>
          <gravity>1</gravity>
        </link>
        <link name='link_2'>
          <pose frame=''>3.31 0.32 0 0 -0 0</pose>
          <visual name='visual_conveyor_model_2'>
            <geometry>
              <mesh>
                <uri>model://conveyor/meshes/model.dae</uri>
                <scale>1 1 1</scale>
              </mesh>
            </geometry>
          </visual>
          <self_collide>0</self_collide>
          <kinematic>0</kinematic>
          <gravity>1</gravity>
        </link>
        <link name='link_3'>
          <pose frame=''>6.62 0.32 0 0 -0 0</pose>
          <visual name='visual_conveyor_model_3'>
            <geometry>
              <mesh>
                <uri>model://conveyor/meshes/model.dae</uri>
                <scale>1 1 1</scale>
              </mesh>
            </geometry>
          </visual>
          <self_collide>0</self_collide>
          <kinematic>0</kinematic>
          <gravity>1</gravity>
        </link>
      </model>
      <model name='conveyor_belt_moving'>
        <static>0</static>
        <pose frame=''>-0.3 0 0.9 0 -0 0</pose>
        <link name='belt'>
          <pose frame=''>5 0 -0.003 0 -0 0</pose>
          <inertial>
            <inertia>
              <ixx>3.8185</ixx>
              <ixy>0</ixy>
              <ixz>0</ixz>
              <iyy>1781.5</iyy>
              <iyz>0</iyz>
              <izz>1784.72</izz>
            </inertia>
            <mass>100</mass>
          </inertial>
          <collision name='belt_collision'>
            <geometry>
              <box>
                <size>9.7 0.68 0.006</size>
              </box>
            </geometry>
            <surface>
              <friction>
                <ode>
                  <mu>1</mu>
                  <mu2>1</mu2>
                </ode>
                <torsional>
                  <coefficient>1000</coefficient>
                  <patch_radius>0.1</patch_radius>
                  <ode/>
                </torsional>
              </friction>
              <contact>
                <ode/>
              </contact>
              <bounce/>
            </surface>
            <max_contacts>10</max_contacts>
          </collision>
          <self_collide>0</self_collide>
          <kinematic>0</kinematic>
          <gravity>1</gravity>
        </link>
      </model>
      <joint name='belt_joint' type='prismatic'>
        <parent>conveyor_belt_fixed::link</parent>
        <child>conveyor_belt_moving::belt</child>
        <axis>
          <xyz>1 0 0</xyz>
          <limit>
            <lower>0</lower>
            <upper>1</upper>
          </limit>
          <use_parent_model_frame>0</use_parent_model_frame>
          <dynamics>
            <spring_reference>0</spring_reference>
            <spring_stiffness>0</spring_stiffness>
          </dynamics>
        </axis>
      </joint>
      <plugin name='conveyor_belt_plugin' filename='libROSConveyorBeltPlugin.so'>
        <robot_namespace/>
        <population_rate_modifier_topic>/conveyor_gazebo/population/rate_modifier</population_rate_modifier_topic>
        <link>conveyor_belt::conveyor_belt_moving::belt</link>
        <max_belt_linear_vel>1.0</max_belt_linear_vel>
        <power>0</power>
      </plugin>
      <pose frame=''>1.2 5 0 0 0 -1.571</pose>
    </model>
    <gravity>0 0 -9.8</gravity>
    <magnetic_field>6e-06 2.3e-05 -4.2e-05</magnetic_field>
    <atmosphere type='adiabatic'/>
    <spherical_coordinates>
      <surface_model>EARTH_WGS84</surface_model>
      <latitude_deg>0</latitude_deg>
      <longitude_deg>0</longitude_deg>
      <elevation>0</elevation>
      <heading_deg>0</heading_deg>
    </spherical_coordinates>
    <model name='conveyor_belt_0'>
      <model name='conveyor_belt_fixed'>
        <static>1</static>
        <pose frame=''>0 0 0 0 -0 0</pose>
        <link name='link'>
          <pose frame=''>0 0.32 0 0 -0 0</pose>
          <visual name='visual_conveyor_model_1'>
            <geometry>
              <mesh>
                <uri>model://conveyor/meshes/model.dae</uri>
                <scale>1 1 1</scale>
              </mesh>
            </geometry>
          </visual>
          <self_collide>0</self_collide>
          <kinematic>0</kinematic>
          <gravity>1</gravity>
        </link>
        <link name='link_2'>
          <pose frame=''>3.31 0.32 0 0 -0 0</pose>
          <visual name='visual_conveyor_model_2'>
            <geometry>
              <mesh>
                <uri>model://conveyor/meshes/model.dae</uri>
                <scale>1 1 1</scale>
              </mesh>
            </geometry>
          </visual>
          <self_collide>0</self_collide>
          <kinematic>0</kinematic>
          <gravity>1</gravity>
        </link>
        <link name='link_3'>
          <pose frame=''>6.62 0.32 0 0 -0 0</pose>
          <visual name='visual_conveyor_model_3'>
            <geometry>
              <mesh>
                <uri>model://conveyor/meshes/model.dae</uri>
                <scale>1 1 1</scale>
              </mesh>
            </geometry>
          </visual>
          <self_collide>0</self_collide>
          <kinematic>0</kinematic>
          <gravity>1</gravity>
        </link>
      </model>
      <model name='conveyor_belt_moving'>
        <static>0</static>
        <pose frame=''>-0.3 0 0.9 0 -0 0</pose>
        <link name='belt'>
          <pose frame=''>5 0 -0.003 0 -0 0</pose>
          <inertial>
            <inertia>
              <ixx>3.8185</ixx>
              <ixy>0</ixy>
              <ixz>0</ixz>
              <iyy>1781.5</iyy>
              <iyz>0</iyz>
              <izz>1784.72</izz>
            </inertia>
            <mass>100</mass>
          </inertial>
          <collision name='belt_collision'>
            <geometry>
              <box>
                <size>9.7 0.68 0.006</size>
              </box>
            </geometry>
            <surface>
              <friction>
                <ode>
                  <mu>1</mu>
                  <mu2>1</mu2>
                </ode>
                <torsional>
                  <coefficient>1000</coefficient>
                  <patch_radius>0.1</patch_radius>
                  <ode/>
                </torsional>
              </friction>
              <contact>
                <ode/>
              </contact>
              <bounce/>
            </surface>
            <max_contacts>10</max_contacts>
          </collision>
          <self_collide>0</self_collide>
          <kinematic>0</kinematic>
          <gravity>1</gravity>
        </link>
      </model>
      <joint name='belt_joint' type='prismatic'>
        <parent>conveyor_belt_fixed::link</parent>
        <child>conveyor_belt_moving::belt</child>
        <axis>
          <xyz>1 0 0</xyz>
          <limit>
            <lower>0</lower>
            <upper>1</upper>
          </limit>
          <use_parent_model_frame>0</use_parent_model_frame>
          <dynamics>
            <spring_reference>0</spring_reference>
            <spring_stiffness>0</spring_stiffness>
          </dynamics>
        </axis>
      </joint>
      <plugin name='conveyor_belt_plugin' filename='libROSConveyorBeltPlugin.so'>
        <robot_namespace/>
        <population_rate_modifier_topic>/conveyor_gazebo/population/rate_modifier</population_rate_modifier_topic>
        <link>conveyor_belt::conveyor_belt_moving::belt</link>
        <max_belt_linear_vel>1.0</max_belt_linear_vel>
        <power>0</power>
      </plugin>
      <pose frame=''>-9.6417 -0.151539 0 0 -0 0</pose>
    </model>
    <state world_name='conveyor_world'>
      <sim_time>0 0</sim_time>
      <real_time>0 0</real_time>
      <wall_time>1667916407 585790069</wall_time>
      <iterations>0</iterations>
      <model name='conveyor_belt'>
        <pose frame=''>1.2 5 0 0 0 -1.571</pose>
        <scale>1 1 1</scale>
        <model name='conveyor_belt_fixed'>
          <pose frame=''>1.2 5 0 0 0 -1.571</pose>
          <scale>1 1 1</scale>
          <link name='link'>
            <pose frame=''>1.52 4.99993 0 0 0 -1.571</pose>
            <velocity>0 0 0 0 -0 0</velocity>
            <acceleration>0 0 0 0 -0 0</acceleration>
            <wrench>0 0 0 0 -0 0</wrench>
          </link>
          <link name='link_2'>
            <pose frame=''>1.51933 1.68993 0 0 0 -1.571</pose>
            <velocity>0 0 0 0 -0 0</velocity>
            <acceleration>0 0 0 0 -0 0</acceleration>
            <wrench>0 0 0 0 -0 0</wrench>
          </link>
          <link name='link_3'>
            <pose frame=''>1.51865 -1.62007 0 0 0 -1.571</pose>
            <velocity>0 0 0 0 -0 0</velocity>
            <acceleration>0 0 0 0 -0 0</acceleration>
            <wrench>0 0 0 0 -0 0</wrench>
          </link>
        </model>
        <model name='conveyor_belt_moving'>
          <pose frame=''>1.20006 5.3 0.9 0 0 -1.571</pose>
          <scale>1 1 1</scale>
          <link name='belt'>
            <pose frame=''>1.19904 0.3 0.897 0 0 -1.571</pose>
            <velocity>0 0 0 0 -0 0</velocity>
            <acceleration>0 0 0 0 -0 0</acceleration>
            <wrench>0 0 0 0 -0 0</wrench>
          </link>
        </model>
      </model>
      <model name='conveyor_belt_0'>
        <pose frame=''>-8.96133 -0.151539 0 0 -0 0</pose>
        <scale>1 1 1</scale>
        <model name='conveyor_belt_fixed'>
          <pose frame=''>-8.96133 -0.151539 0 0 -0 0</pose>
          <scale>1 1 1</scale>
          <link name='link'>
            <pose frame=''>-8.96133 0.168461 0 0 -0 0</pose>
            <velocity>0 0 0 0 -0 0</velocity>
            <acceleration>0 0 0 0 -0 0</acceleration>
            <wrench>0 0 0 0 -0 0</wrench>
          </link>
          <link name='link_2'>
            <pose frame=''>-5.65133 0.168461 0 0 -0 0</pose>
            <velocity>0 0 0 0 -0 0</velocity>
            <acceleration>0 0 0 0 -0 0</acceleration>
            <wrench>0 0 0 0 -0 0</wrench>
          </link>
          <link name='link_3'>
            <pose frame=''>-2.34133 0.168461 0 0 -0 0</pose>
            <velocity>0 0 0 0 -0 0</velocity>
            <acceleration>0 0 0 0 -0 0</acceleration>
            <wrench>0 0 0 0 -0 0</wrench>
          </link>
        </model>
        <model name='conveyor_belt_moving'>
          <pose frame=''>-9.26133 -0.151539 0.9 0 -0 0</pose>
          <scale>1 1 1</scale>
          <link name='belt'>
            <pose frame=''>-4.26133 -0.151539 0.897 0 -0 0</pose>
            <velocity>0 0 0 0 -0 0</velocity>
            <acceleration>0 0 0 0 -0 0</acceleration>
            <wrench>0 0 0 0 -0 0</wrench>
          </link>
        </model>
      </model>
      <model name='ground_plane'>
        <pose frame=''>0 0 0 0 -0 0</pose>
        <scale>1 1 1</scale>
        <link name='link'>
          <pose frame=''>0 0 0 0 -0 0</pose>
          <velocity>0 0 0 0 -0 0</velocity>
          <acceleration>0 0 0 0 -0 0</acceleration>
          <wrench>0 0 0 0 -0 0</wrench>
        </link>
      </model>
      <light name='sun'>
        <pose frame=''>0 0 10 0 -0 0</pose>
      </light>
    </state>
    <gui fullscreen='0'>
      <camera name='user_camera'>
        <pose frame=''>1.77433 -15.9532 10.6918 0 0.627643 1.6362</pose>
        <view_controller>orbit</view_controller>
        <projection_type>perspective</projection_type>
      </camera>
    </gui>
  </world>
</sdf>
